Traceback (most recent call last):
  File "/Users/vahid/ComputationalPhysics/lib/python3.13/site-packages/jupyter_cache/executors/utils.py", line 58, in single_nb_execution
    executenb(
    ~~~~~~~~~^
        nb,
        ^^^
    ...<4 lines>...
        **kwargs,
        ^^^^^^^^^
    )
    ^
  File "/Users/vahid/ComputationalPhysics/lib/python3.13/site-packages/nbclient/client.py", line 1319, in execute
    return NotebookClient(nb=nb, resources=resources, km=km, **kwargs).execute()
           ~~~~~~~~~~~~~~~~~~~~~~~~~~~~~~~~~~~~~~~~~~~~~~~~~~~~~~~~~~~~~~~~~~~^^
  File "/Users/vahid/ComputationalPhysics/lib/python3.13/site-packages/jupyter_core/utils/__init__.py", line 165, in wrapped
    return loop.run_until_complete(inner)
           ~~~~~~~~~~~~~~~~~~~~~~~^^^^^^^
  File "/usr/local/Cellar/python@3.13/3.13.1/Frameworks/Python.framework/Versions/3.13/lib/python3.13/asyncio/base_events.py", line 720, in run_until_complete
    return future.result()
           ~~~~~~~~~~~~~^^
  File "/Users/vahid/ComputationalPhysics/lib/python3.13/site-packages/nbclient/client.py", line 709, in async_execute
    await self.async_execute_cell(
        cell, index, execution_count=self.code_cells_executed + 1
    )
  File "/Users/vahid/ComputationalPhysics/lib/python3.13/site-packages/nbclient/client.py", line 1062, in async_execute_cell
    await self._check_raise_for_error(cell, cell_index, exec_reply)
  File "/Users/vahid/ComputationalPhysics/lib/python3.13/site-packages/nbclient/client.py", line 918, in _check_raise_for_error
    raise CellExecutionError.from_cell_and_msg(cell, exec_reply_content)
nbclient.exceptions.CellExecutionError: An error occurred while executing the following cell:
------------------
### HANDSON: Write a loop to print squares of numbers.

# Your turn: Print squares
...
    print(f"Square of {i} is {i ** 2}")
------------------


[0;36m  Cell [0;32mIn[11], line 5[0;36m[0m
[0;31m    print(f"Square of {i} is {i ** 2}")[0m
[0m    ^[0m
[0;31mIndentationError[0m[0;31m:[0m unexpected indent


